<!DOCTYPE html>
<html>
  <head>
    <title>CS 246 :: Exception Handling</title>
    <meta charset="utf-8">
    <meta http-equiv="X-UA-Compatible" content="IE=edge">
    <meta name="viewport" content="width=device-width, shrink-to-fit=no, initial-scale=1">
    <meta name="Course Notes" content="">
    <meta name="Raphael" content="">

    <!-- Bootstrap Core CSS -->
    <link href="../../css/bootstrap.min.css" rel="stylesheet">

    <!-- Custom CSS -->
    <link href="../../css/simple-sidebar.css" rel="stylesheet">
    <link href="../css/styles.css" rel="stylesheet">
    <script src="https://cdn.rawgit.com/google/code-prettify/master/loader/run_prettify.js?lang=cpp&lang=bsh&skin=sunburst"></script>
  </head>
  <body>
    <div id="wrapper">
      <!-- Sidebar -->
      <div id="sidebar-wrapper">
        <ul class="sidebar-nav">
          <li class="sidebar-brand">
            <a href="./home.html">CS 246 Home</a>
          </li>
          <li><a href="#1">Try-Catch</a></li>
          <li><a href="#2">Defining Your Own Exception Class</a></li>
          <li><a href="#3">Multiple Throws And Catches</a></li>
          <li><a href="#4">Throwing Exceptions In Functions</a></li>
          <li><a href="#5">Exception Specification</a></li>
          <li><a href="#6">Inheritance</a></li>
          <li><a href="#7">4 Levels of Exception Safety</a></li>
          <li><a href="#8">STL Vectors</a></li>
        </ul>
      </div>
      <!-- /#sidebar-wrapper -->

      <!-- Page Content -->
      <div id="page-content-wrapper">
          <div class="container-fluid">
            <div class="row">
              <div class="col-lg-12">
                <a href="#menu-toggle" class="btn btn-default" id="menu-toggle">Toggle Menu</a>
                <h1 id="title_text">Exception Handling</h1><br />

                <!-- Table of Contents -->
                <div id="contents">
                  <h1>Table of Contents</h1>
                  <ol id="nav">
                    <li><a href="#1">Try-Catch</a></li>
                    <li><a href="#2">Defining Your Own Exception Class</a></li>
                    <li><a href="#3">Multiple Throws And Catches</a></li>
                    <li><a href="#4">Throwing Exceptions In Functions</a></li>
                    <li><a href="#5">Exception Specification</a></li>
                    <li><a href="#6">Inheritance</a></li>
                    <li><a href="#7">3 Levels of Exception Safety</a></li>
                    <li><a href="#8">STL Vectors</a></li>
                  </ol>
                </div>
                <!--Table of Contents -->
                <br />
                <b>Exception handling</b> is the process where we deal with exceptional cases/edge cases.  In general, exceptions are always preferred over using error codes in terms of program design.  For example, consider the following example:
<pre class="prettyprint">
int milk, donuts;
cin << milk << donuts;

double dpg = donuts / static_cast&lt;double>(milk);
cout << dpg;</pre>
                This code assumes that <code>milk != 0</code>.  If <code>milk == 0</code>, then there be an error due to division by zero.  One way to handle this is by if statements.  The other way is using <b>try-catch blocks</b>.

                <h2 id="1">Try-Catch</h2>
<pre class="prettyprint">
try {
  int milk, donuts;
  cin << milk << donuts;

  if (milk <= 0) throw donuts;

  double dpg = donuts / static_cast&lt;double>(milk);
  cout << dpg;
} catch(int e) {
  cout << "We have " << e << " donuts, and no milk!" << endl;
}</pre>

                <h3>Try Block</h3>
                The <b>try block</b> contains the code that tells the program what to do when everything goes smoothly.  If something unusual happens, we throw an exception, and flow of control is transferred to the catch block.

                <h3>Catch Block</h3>
                The <b>catch block</b> contains code that executes when the try block throws an exception.  Executing the catch block is known as "catching the exception" or "handling the exception".  The catch block takes in a catch-block parameter, which is preceded by a type name that specifies the type of thrown value that the catch block can catch.  The catch-block parameter also gives a name for the thrown value to be used in the catch block.  If no parameter is needed, the variable name can be left out (see <a class="link" href="#3">below</a>).
                <br />
                <code class="prettyprint">catch(...)</code> is a special kind of <code>catch</code> block that can be used to catch a thrown value of any type.

                <h3>Nested Try-Catch Blocks</h3>
                If an exception is thrown in the inner try block but not caught in any of the inner catch blocks, then the exception is thrown to the outer try block and possibly caught by an outer catch block.

                <h2 id="2">Defining Your Own Exception Class</h2>
                It is common to define a class whose objects can carry precise info on what is thrown to the catch block.  This allows us to have a different type to identify each possible kind of exceptional situation.  An exception class is just a class, for example:
<pre class="prettyprint">
class NoMilk {
public:
  NoMilk(){}
  NoMilk(int num) : count(num) {}
  int getCount() const {return count;}
private:
  int count;
}
int main () {
  try {
    int milk, donuts;
    cin << milk << donuts;

    if (milk <= 0) throw NoMilk(donuts);

    double dpg = donuts / static_cast&lt;double>(milk);
    cout << dpg;
  } catch(NoMilk e) {
    cout << "We have " << e.getCount() << " donuts, and no milk!" << endl;
  }
}</pre>

                <h3>Trivial Exception Class</h3>
                Exception classes with no member data can be defined as it allows us to throw an object of that class and activate the appropriate catch block. e.g. <code class="prettyprint">class DivideByZero{};</code>

                <h2 id="3">Multiple Throws And Catches</h2>
                A try block can throw any numnber of exception values.  When catching multiple exceptions the order of the catch blocks can be important.  The catch blocks are tried in order, so it is recommended to place more specific exceptions first and more generic exceptions last.
<pre class="prettyprint">
try {
  int milk, donuts;
  cin << milk << donuts;

  if (milk < 0) throw NegativeNumber("milk");
  if (milk == 0) throw DivideByZero();

  double dpg = donuts / static_cast&lt;double>(milk);
  cout << dpg;
} catch(NegativeNumber e) {
  cout << "Cannot have a negative number of " << e.getMessage() << endl;
} catch (DivideByZero) {  // no need to give parameter if not used
  cout << "ERROR: DIVIDE BY ZERO!";
}</pre>
                <h2 id="4">Throwing Exceptions In Functions</h2>
                If we want to define the catch block outside of a function, the function can throw an exception that is handled when the function is called within a try block.
<pre class="prettyprint">
try {
  quotient = safeDivide(num, denom);
} catch(DivideByZero) {
  cout << "ERROR: DIVSION BY ZERO!";
}
// Function throws to outer try-catch block
double safeDivide(int top, int bot) throw (DivideByZero) {
  if (bottom == 0) throw DivideByZero();
  return top / static_cast<double> (bottom);
}</pre>

                <h2 id="5">Exception Specification</h2>
                The <b>exception specification</b>, also known as the <b>throw list</b>, lists the types of exceptions that the function might throw but does not handle/catch.  Exception specifications appear in both the function declaration and definition and if there are multiple function declarations, all of them must have identical exception specifications.  If there are multiple possible exceptions, the exception types are separated by commas. i.e. <code class="prettyprint">void foo() throw (DivideByZero, SomeOtherException);</code><br />
                If a function should not throw any exceptions that are caught inside the function, we use an empty exception specification, <code class="prettyprint">void foo() throw ();</code><br />
                Any exceptions that are not included in the throw list invoke <code>unexpected()</code>.  The behaviour of <code>unexpected()</code> can be changed with <code>set_unexpected()</code> (which takes in the new function as its parameter), but its default action is to call <code>terminate()</code> which ends the program.

                <h3>In Practice</h3>
                Exception specifications have no been proven useful in practice:
                <ul>
                  <li>
                    Run-time checking:
                    <ul>
                      <li>exception specifications are checked at runtime rather than at compile time. Does not guarantee that all exceptions have been handled.</li>
                      <li>unhandled exceptions call <code>std::unexpected()</code> which defaults to terminating the program.</li>
                    </ul>
                  </li>
                  <li>
                    Run-time overhead:
                    <ul>
                      <li>Run-time checking requires the compiler to produce additional code.  Affects optimizations.</li>
                    </ul>
                  </li>
                  <li>
                    Unusable in generic code:
                    <ul>
                      <li> not generally possible to know what types of exceptions may be thrown, so a precise exception specification cannot be written.</li>
                    </ul>
                  </li>
                </ul>
                In practice, only two forms of exception-throwing guarantees are useful:
                <ol>
                  <li>might throw any exception: omit exception-specification</li>
                  <li>will never throw any exception: noexcept (see below)</li>
                </ol>

                <div class="note">
                  <div>
                    <h3>noexcept</h3>
                    In C++11, <code>throw</code> has been deprecated.  Instead we use <code>noexcept()</code> which takes in an expression (but does not evaluate it). <br /> If a function might throw an exception, we omit any throw statement or use <code class="prettyprint">noexcept(false)</code><br />
                    If a function does not throw, use <code class="prettyprint">noexcept</code> or <code class="prettyprint">noexcept(true)</code><br />
                    e.g. <code>void f() noexcept;  // f does not throw</code>
                  </div>
                </div>
                If you know a function will never throw or propagate an exception, declare it <code>noexcept</code> because it will facilitate optimization of your code.

                <h2 id="6">Inheritance</h2>
                Exception class hierarchies are useful.
                If we have a derived class <code>D</code> of class <code>B</code>, and <code>B</code> is in the exception specification, then a thrown <code>D</code> will be caught.

                <h2 id="7">Programming Techniques For Exception Handling</h2>
                <ol>
                  <li>
                    Separate throwing and catching into separate functions - throw within a function definition and list it in the exception specification, but place the catch clause in a different function
                  </li>
                  <li>
                    <u>Never</u> let the destructor throw an exception as it might be called when dealing with another exception
                  </li>
                  <li>
                    Exceptions should be used sparingly as they alter the flow of control.  As a good rule of thumb, if a throw is desired, consider how to do it without the throw and if reasonable, do that instead.
                  </li>
                </ol>

                <h2 id="7">4 Levels of Exception Safety</h2>
                There are 4 levels of exception safety:
                <ol>
                  <li>
                    No Guarantee
                    <ul>
                      <li>If an exception occurs, it will not be handled</li>
                      <li>Memory can be leaked</li>
                      <li>Class invariants can be violated</li>
                    </ul>
<pre class="prettyprint">
class A {
  int *i;
  A(int *i) : i { i } {}
  ~A() { delete i; }
}
</pre>
                    If an error occurs and an exception is thrown with an object of type <code>A</code>, the destructor will not be called and there will be a memory leak.  This does no have any exception handling thus it has no guarantee.
                  </li>
                  <li>
                    Basic Guarantee
                    <ul>
                      <li>If an exception occurs, the program is valid, but in an unspecified state</li>
                      <li>Nothing is leaked</li>
                      <li>Class invariants are maintained</li>
                      <li>e.g. Regular copy constructor where data is lost</li>
                    </ul>
                    e.g.
<pre class="prettyprint">
class A {}
class B {}
class C {
  A a;
  B b;
public:
  void f() {
    a.method1();
    b.method2();
  }
};</pre>
                    If <code>a.method1() </code>runs and <code>b.method2()</code> has an error, the state of <code>a</code> is changed without <code>b</code> changing.  This results in a <b>partial function</b>.<br />
                  </li>
                  <li>
                    Strong Guarantee
                    <ul>
                      <li>Exception is raised while executing error</li>
                      <li>The state of the program will be as if the function had not been called</li>
                      <li>e.g. Copy and Swap idiom</li>
                    </ul>
                  </li>
                  e.g.
<pre class="prettyprint">
class C {
  A a;
  B b;
public:
  void f() {
    A aTemp = a;  // calls copy ctor
    B bTemp = b;
    aTemp.method1();
    bTemp.method2();
    std::swap(a, aTemp);  // nothrow
    std::swap(b, bTemp);  // nothrow
  }
}</pre>
                  If we had used a copy assignment operator instead of <code>swap</code>, we would not have a strong exception guarantee because copy assignment operator could throw.  The non-throwing <code>swap</code> ensures that the state of <code>a</code> and <code>b</code> are not changed if the above methods fail.
                  <br />
                  <li>
                    Nothrow Guarantee
                    <ul>
                      <li>Function will never throw an exception</li>
                      <li>no exception is emitted outside of the function</li>
                      <li>Always accomplishes its task</li>
                      <li>use <code>noexcept</code></li>
                    </ul>
                  </li>
                  A possible further enhancement to the above example with strong guarantee is to use pointers via the pImpl idiom as copying pointers cannot throw exceptions.  This provides a nothrow guarantee.  i.e.
<pre class="prettyprint">
struct Cimpl {
 A a;
 B b;
}
class C {
 unique_ptr<CImpl> pImpl;  // pointer to implementation
public:
 auto temp = make_unique<CImpl>(*pImpl);
 // if temp == nullptr, nothing happens
 temp->a.method1();
 temp->b.method2();
 std::swap(pImpl, temp);
};  // Nothrow</pre>
                </ol>

                <h2 id="8">STL Vectors</h2>
                Vectors (more on vectors <a href="./arrays.html#8">here</a>) encapsulate heal-allocated arrays.  This is a form of the <a href="./softeng.html#12">RAII</a> idiom because when the stack-allocated vector goes out of scope, the internal heap-allocated array is freed.
                <br /><code class="prettyprint">void f() { vector<MyClass> v; }</code><br />
                When <code>v</code> goes out of scope, the <code>MyClass</code> destructor runs on all items in the array and the array is freed.<br />
                <code class="prettyprint">void g(){ vector<MyClass*> v; }</code><br />
                When <code>v</code> goes out of scope, pointers dont have destructors, so only the array is freed while pointers are not.  To fix this, we can use shared pointers: <code class="prettyprint">void h() { vector<shared_ptr<MyClass>> v; }</code><br />

                <h3>Emplace Back</h3>
                <code class="prettyprint">vector&lt;T>::emplace_back</code> offers strong guarantee because if the array is full, it:
                <ol>
                  <li>allocates a new, larger array</li>
                  <li>copy the objects over via copy constructor</li>
                  <li>If copy constructor throws:
                    <ol type="i">
                      <li>destroys new array</li>
                      <li>old array is intact</li>
                      <li>strong guarantee</li>
                    </ol>
                  </li>
                  <li>else delete old array</li>
                </ol>
                Consider the move constructor.  With the move constructor,<code>emplace_back</code> will:
                <ol>
                  <li>allocate new larger array</li>
                  <li>move the objects over</li>
                  <li>delete old array</li>
                </ol>
                The problem is that if the move constructor were to throw, <code>emplace_back</code> wouldn't offer strong guarantee because the original array would no longer be intact.  However, <code>emplace_back</code> promises the strong guarantee, so if the move constructor offers nothrow guarantee, <code>emplace_back</code> will use it, otherwise it will use the copy constructor which may be slower.
                <div class="note">
                  <div>
                    <h3>Rule of Thumb</h3>
                    Move operations should provide nothrow guarantee if possible and should indicate that they do so.
<pre class="prettyprint">
class MyClass {
public:
  MyClass(MyClass &&other) noexcept {}
  MyClass &operator=(MyClass &&other) noexcept {}
}</pre>

                  </div>
                </div>

              </div>
            </div>
        </div>
        <footer class="footer">
          <a href="#top">Back to Top</a>
          <p id="last_modified"></p>
        </footer>
      </div>
      <!-- /#page-content-wrapper -->

    </div>
    <!-- /#wrapper -->

    <!-- jQuery -->
    <script src="../../js/jquery.js"></script>

    <!-- Bootstrap Core JavaScript -->
    <script src="../../js/bootstrap.min.js"></script>

    <!-- JS Script -->
    <script src="../../js/scripts.js"></script>

  </body>
</html>
